Workbook

Sheet Utilities Sector – Overview
B1: Utilities Sector – Business Model, Contract Structure & Risk Classification
B2: The Utilities sector includes companies engaged in generation, transmission, and distribution of essential services such as electricity, gas, LNG, and water. These services are critical for economic activity and daily consumption.
B4: • Power purchase agreements (PPAs)
B5: • Regulated tariffs approved by government bodies
B6: • Volume growth (electricity/gas demand)
B7: • Capacity addition and utilization
B8: • Industrial, commercial, and household consumption
B10: Company | C10: Segment | D10: Fuel / Business | E10: PPA / Contract | F10: Revenue Stability | G10: Key Risk | H10: SEB / Client Exposure | I10: Utility Type | J10: Remarks
B11: Adani Energy Solutions Limited | C11: Power Transmission | D11: Transmission | E11: Regulated | F11: Very High | G11: Minimal | H11: Low | I11: Core Utility | J11: Regulated returns
B12: Adani Green Energy Limited | C12: Renewable Power | D12: Solar/Wind | E12: PPAs | F12: High | G12: High valuation | H12: Medium | I12: Core Utility | J12: Renewable focused
B13: Adani Power Limited | C13: Power Generation | D13: Imported Coal | E13: PPAs | F13: Medium | G13: Fuel price risk | H13: Medium | I13: Core Utility | J13: Generation business
B14: Adani Total Gas Limited | C14: City Gas Distribution | D14: Natural Gas | E14: Regulated CGD | F14: High | G14: Valuation | H14: Low | I14: Core Utility | J14: Stable gas utility
B15: Agni Green Power Limited | C15: Renewable Power | D15: Solar | E15: PPAs | F15: Low | G15: Scale | H15: Medium | I15: Core Utility | J15: Renewable focused
B16: Apex Ecotech Limited | C16: Environmental Services | D16: Waste | E16: Project-based | F16: Low | G16: Execution risk | H16: Low | I16: EPC | J16: Non-core utility
B17: CESC Limited | C17: Power Distribution | D17: Coal | E17: PPAs | F17: High | G17: Regulatory | H17: Low | I17: Core Utility | J17: Non-core utility
B18: EKI Energy Services Limited | C18: Carbon Advisory | D18: Carbon credits | E18: Service contracts | F18: Medium | G18: Market volatility | H18: Medium | I18: Service | J18: Non-core utility
B19: Energy Development Company Limited | C19: Power Generation | D19: Renewable | E19: PPAs | F19: Medium | G19: Project scale | H19: Medium | I19: Core Utility | J19: Generation business
B20: GAIL (India) Limited | C20: Gas Transmission | D20: Natural Gas | E20: Long-term contracts | F20: High | G20: Gas policy | H20: Low | I20: Core Utility | J20: Stable gas utility
B21: Gita Renewable Energy Limited | C21: Renewable Power | D21: Solar/Wind | E21: PPAs | F21: Low | G21: Scale | H21: Medium | I21: Core Utility | J21: Renewable focused
... B69: Waaree Renewable Technologies Limited | C69: Renewable EPC | D69: Solar | E69: Project-based | F69: Medium | G69: Execution | H69: Medium | I69: EPC | J69: Renewable focused
B73: Source: Company Annual Reports, Investor Presentations, Regulatory Filings (PNGRB/CERC/SERC), Business Descriptions from Screener, Moneycontrol & Company Websites
B75: Segment | C75: Company business description (Annual Report / Screener)
B76: Fuel / Business | C76: Fuel mix disclosed in AR / Investor PPT
B77: PPA / Contract | C77: PPAs, CGD regulation, take-or-pay contracts
B78: Revenue Stability | C78: Derived from contract nature
B79: Key Risk | C79: Derived from sector + balance sheet reality
B80: SEB / Client Exposure | C80: Exposure to DISCOMs / Govt / private clients
B81: Utility Type | C81: Core vs Non-core based on essential utility definition
B82: Remarks | C82: Analyst conclusion (final takeaway)
B85: Below is the remark rule is used for the companies
B86: Condition | C86: Remark
B87: Regulated / PPAs / Essential service | C87: Stable utility
B88: Power generation under PPAs | C88: Generation business
B89: EPC / Trading / Infra | C89: Non-core utility
B90: Renewables + PPAs | C90: Renewable focused
B91: Execution-heavy infra | C91: Execution risk
B93: Examples:
B94: City Gas Distribution (Adani Total Gas, IGL, MGL, Gujarat Gas) | C94: Regulated CGD companies with predictable volumes and tariff protection. High revenue stability with low SEB exposure and gas price risk as key variable. Remarks logic:"Stable gas utility" because regulation + annuity-like cash flows.
B95: Gas Transmission (GAIL, GSPL, GSPC) | C95: Operate regulated pipelines with long-term contracts and assured returns. Minimal volume risk and high revenue visibility. Remarks: "Stable gas utility" / "Regulated returns".
B96: Hydro & PSU Generators (NHPC, SJVN, NTPC) | C96: Power sold under long-term PPAs with state utilities. Very high revenue stability but exposed to hydrology or SEB payment delays. Remkars: "Generation Business" (core utility)
...

Sheet Industry Overview
B1: List of Companies Covered – Utilities Sector
B2: Coverage includes Power, Gas, LNG, Renewable Utilities
B4: Company Name | C4: Market cap | D4: Price | E4: Change % | F4: Volume | G4: Rel Volume | H4: P/E | I4: EPS dil | J4: EPS dil growth | K4: Div yield % | L4: Analyst Rating | M4: Symbol | N4: Price
B5: NTPCNTPC Limtied | C5: . | D5: 319.50 INR | E5: −1.18% | F5: 7.91 M | G5: 1.01 | H5: 13.04 | I5: 24.49 INR | J5: 0.076 | K5: 0.0266 | L5: Buy | M5: NTPCNTPC Limited | N5: 319.50 INR
B6: ADANIPOWERAdani Power Limited | C6: 2.77 T INR | D6: 139.04 INR | E6: −3.30% | F6: 14.99 M | G6: 1.39 | H6: 22.29 | I6: 6.24 INR | J6: −5.41% | K6: 0 | L6: Strong buy | M6: ADANIPOWERAdani Power Limited | N6: 139.04 INR
B7: POWERGRIDPower Grid Corporation of India Limited | C7: 2.51 T INR | D7: 265.20 INR | E7: −1.70% | F7: 10.2 M | G7: 0.76 | H7: 16.28 | I7: 16.29 INR | J7: −3.57% | K7: 0.0334 | L7: Buy | M7: POWERGRIDPower Grid Corporation of India Limited | N7: 265.20 INR
B8: ADANIGREENAdani Green Energy Limited | C8: 1.67 T INR | D8: 993.80 INR | E8: −2.35% | F8: 1.31 M | G8: 0.84 | H8: 79.59 | I8: 12.49 INR | J8: 0.8046 | K8: 0 | L8: Strong buy | M8: ADANIGREENAdani Green Energy Limited | N8: 993.80 INR
B9: TATAPOWERTata Power Company Limited | C9: 1.23 T INR | D9: 374.15 INR | E9: −2.69% | F9: 7.01 M | G9: 1.53 | H9: 29.5 | I9: 12.68 INR | J9: 0.0829 | K9: 0.0059 | L9: Neutral | M9: TATAPOWERTata Power Company Limited | N9: 374.15 INR
B10: ADANIENSOLAdani Energy Solutions Ltd | C10: 1.18 T INR | D10: 960.50 INR | E10: −1.87% | F10: 1.41 M | G10: 1.65 | H10: 51.16 | I10: 18.77 INR | J10: 3.2813 | K10: 0 | L10: Strong buy | M10: ADANIENSOLAdani Energy Solutions Ltd | N10: 960.50 INR
B11: GAILGAIL (India) Limited | C11: 1.12 T INR | D11: 166.81 INR | E11: −1.86% | F11: 10.88 M | G11: 0.75 | H11: 10.05 | I11: 16.60 INR | J11: −5.42% | K11: 0.0441 | L11: Buy | M11: GAILGAIL (India) Limited | N11: 166.81 INR
B12: ENRINSiemens Energy India Limited | C12: 1.1 T INR | D12: 2,953.80 INR | E12: −4.66% | F12: 518.82 K | G12: 0.24 | H12: — | I12: — | J12: — | K12: 0 | L12: Neutral | M12: ENRINSiemens Energy India Limited | N12: 2,953.80 INR
B13: JSWENERGYJSW Energy Limited | C13: 806.42 B INR | D13: 453.85 INR | E13: −1.75% | F13: 3.06 M | G13: 1.04 | H13: 39.18 | I13: 11.58 INR | J13: 0.0145 | K13: 0.0043 | L13: Buy | M13: JSWENERGYJSW Energy Limited | N13: 453.85 INR
B14: NHPCNHPC Limited | C14: 774.47 B INR | D14: 76.43 INR | E14: −0.83% | F14: 9.18 M | G14: 0.91 | H14: 24.21 | I14: 3.16 INR | J14: 0.0645 | K14: 0.0248 | L14: Neutral | M14: NHPCNHPC Limited | N14: 76.43 INR
B15: NTPCGREENNTPC Green Energy Limited | C15: 768.65 B INR | D15: 90.27 INR | E15: −1.03% | F15: 2.9 M | G15: 0.73 | H15: 124.96 | I15: 0.72 INR | J15: — | K15: 0 | L15: Neutral | M15: NTPCGREENNTPC Green Energy Limited | N15: 90.27 INR
B16: ATGLAdani Total Gas Ltd. | C16: 652.08 B INR | D16: 577.05 INR | E16: −2.71% | F16: 663.92 K | G16: 2.22 | H16: 101.43 | I16: 5.69 INR | J16: −10.87% | K16: 0.0004 | L16: Neutral | M16: ATGLAdani Total Gas Ltd. | N16: 577.05 INR
B17: TORNTPOWERTorrent Power Limited | C17: 647.26 B INR | D17: 1,255.10 INR | E17: −2.70% | F17: 316.75 K | G17: 0.93 | H17: 21.04 | I17: 59.66 INR | J17: 0.2783 | K17: 0.0148 | L17: Neutral | M17: TORNTPOWERTorrent Power Limited | N17: 1,255.10 INR
B18: PETRONETPetronet Lng Limited | C18: 412.28 B INR | D18: 270.80 INR | E18: −1.46% | F18: 1.51 M | G18: 0.5 | H18: 11.07 | I18: 24.46 INR | J18: −7.20% | K18: 0.0364 | L18: Neutral | M18: PETRONETPetronet Lng Limited | N18: 270.80 INR
B19: NLCINDIANLC India Limited | C19: 333.83 B INR | D19: 236.85 INR | E19: −1.07% | F19: 984.08 K | G19: 1.08 | H19: 12.57 | I19: 18.84 INR | J19: 0.4231 | K19: 0.0125 | L19: Strong buy | M19: NLCINDIANLC India Limited | N19: 236.85 INR
B20: SJVNSJVN Limited | C20: 291 B INR | D20: 71.24 INR | E20: −3.82% | F20: 4.69 M | G20: 1.88 | H20: 50.28 | I20: 1.42 INR | J20: −44.22% | K20: 0.0197 | L20: Neutral | M20: SJVNSJVN Limited | N20: 71.24 INR
B21: GUJGASLTDGujarat Gas Ltd. | C21: 279.83 B INR | D21: 400.40 INR | E21: −1.51% | F21: 257.03 K | G21: 0.56 | H21: 24.69 | I21: 16.22 INR | J21: −12.17% | K21: 0.0143 | L21: Neutral | M21: GUJGASLTDGujarat Gas Ltd. | N21: 400.40 INR
B22: IGLIndraprastha Gas Limited | C22: 268.31 B INR | D22: 185.02 INR | E22: −3.53% | F22: 1.34 M | G22: 0.48 | H22: 16.22 | I22: 11.41 INR | J22: −13.51% | K22: 0.0222 | L22: Buy | M22: IGLIndraprastha Gas Limited | N22: 185.02 INR
B23: CESCCESC Ltd | C23: 230.65 B INR | D23: 168.42 INR | E23: −3.21% | F23: 778.26 K | G23: 0.58 | H23: 15.4 | I23: 10.94 INR | J23: 0.0269 | K23: 0.0345 | L23: Strong buy | M23: CESCCESC Ltd | N23: 168.42 INR
B24: GSPLGujarat State Petronet Limited | C24: 165.54 B INR | D24: 290.45 INR | E24: −0.97% | F24: 272.79 K | G24: 0.09 | H24: 14.75 | I24: 19.69 INR | J24: −33.05% | K24: 0.017 | L24: Buy | M24: GSPLGujarat State Petronet Limited | N24: 290.45 INR
B25: RPOWERReliance Power Limited | C25: 155.88 B INR | D25: 35.40 INR | E25: −6.05% | F25: 47.51 M | G25: 1.34 | H25: 51.45 | I25: 0.69 INR | J25: −76.33% | K25: 0 | L25: Neutral | M25: RPOWERReliance Power Limited | N25: 35.40 INR
B26: NAVANava Limited | C26: 148.99 B INR | D26: 515.95 INR | E26: −1.99% | F26: 202.11 K | G26: 0.79 | H26: 15.94 | I26: 32.37 INR | J26: −17.68% | K26: 0.0171 | L26: Neutral | M26: NAVANava Limited | N26: 515.95 INR
B27: SWANCORPSwan Corp Limited | C27: 140.16 B INR | D27: 444.00 INR | E27: −0.65% | F27: 1.26 M | G27: 2.11 | H27: 23.98 | I27: 18.52 INR | J27: 0.6417 | K27: 0.0002 | L27: Neutral | M27: SWANCORPSwan Corp Limited | N27: 444.00 INR
B28: JPPOWERJaiprakash Power Ventures Limited | C28: 129.74 B INR | D28: 18.29 INR | E28: −3.33% | F28: 49.46 M | G28: 0.51 | H28: 22.86 | I28: 0.80 INR | J28: −50.89% | K28: 0 | L28: Neutral | M28: JPPOWERJaiprakash Power Ventures Limited | N28: 18.29 INR
B29: MGLMahanagar Gas Ltd | C29: 115.55 B INR | D29: 1,122.40 INR | E29: −4.07% | F29: 202.25 K | G29: 1.28 | H29: 11.34 | I29: 98.96 INR | J29: −14.38% | K29: 0.0256 | L29: Buy | M29: MGLMahanagar Gas Ltd | N29: 1,122.40 INR
B30: WAAREERTLWaaree Renewable Technologies Ltd | C30: 102.78 B INR | D30: 943.10 INR | E30: −4.26% | F30: 602.47 K | G30: 2.1 | H30: 28.15 | I30: 33.50 INR | J30: 0.7446 | K30: 0.002 | L30: Neutral | M30: WAAREERTLWaaree Renewable Technologies Ltd | N30: 943.10 INR
B31: KPIGREENKPI Green Energy Limited | C31: 83.51 B INR | D31: 395.10 INR | E31: −6.72% | F31: 1.93 M | G31: 2.32 | H31: 19.76 | I31: 19.99 INR | J31: 0.5821 | K31: 0.002 | L31: Strong buy | M31: KPIGREENKPI Green Energy Limited | N31: 395.10 INR
B32: INOXGREENInox Green Energy Services Ltd. | C32: 75.9 B INR | D32: 197.03 INR | E32: −4.53% | F32: 1.46 M | G32: 1.64 | H32: 121.31 | I32: 1.62 INR | J32: 0.6614 | K32: 0 | L32: Neutral | M32: INOXGREENInox Green Energy Services Ltd. | N32: 197.03 INR
B33: RELINFRAReliance Infrastructure Limited | C33: 63.19 B INR | D33: 146.97 INR | E33: −5.00% | F33: 1.01 M | G33: 0.93 | H33: 3.1 | I33: 47.47 INR | J33: −40.56% | K33: 0 | L33: Neutral | M33: RELINFRAReliance Infrastructure Limited | N33: 146.97 INR
B34: RTNPOWERRattanIndia Power Limited | C34: 52.09 B INR | D34: 9.34 INR | E34: −3.71% | F34: 12.71 M | G34: 1.27 | H34: 58.59 | I34: 0.16 INR | J34: −99.16% | K34: 0 | L34: Neutral | M34: RTNPOWERRattanIndia Power Limited | N34: 9.34 INR
B35: PTCPTC India Limited | C35: 46.31 B INR | D35: 152.57 INR | E35: −2.50% | F35: 790.51 K | G35: 1.23 | H35: 5.04 | I35: 30.25 INR | J35: 0.608 | K35: 0.0748 | L35: Strong buy | M35: PTCPTC India Limited | N35: 152.57 INR
B36: PACEDIGITKPace Digitek Limited | C36: 44.85 B INR | D36: 200.93 INR | E36: −3.28% | F36: 599.02 K | G36: 0.61 | H36: — | I36: — | J36: — | K36: 0 | L36: Strong buy | M36: PACEDIGITKPace Digitek Limited | N36: 200.93 INR
B37: SGMARTSG Mart Ltd | C37: 40.98 B INR | D37: 337.95 INR | E37: −1.63% | F37: 62.91 K | G37: 0.66 | H37: 33.61 | I37: 10.06 INR | J37: 0.1977 | K37: 0 | L37: Strong buy | M37: SGMARTSG Mart Ltd | N37: 337.95 INR
B38: RELTDRavindra Energy Ltd. | C38: 27.56 B INR | D38: 147.11 INR | E38: −4.21% | F38: 122.91 K | G38: 0.93 | H38: 38.28 | I38: 3.84 INR | J38: — | K38: 0 | L38: Neutral | M38: RELTDRavindra Energy Ltd. | N38: 147.11 INR
B39: GIPCLGujarat Industries Power Co. Ltd. | C39: 24.08 B INR | D39: 146.20 INR | E39: −5.84% | F39: 724.85 K | G39: 3.1 | H39: 12.02 | I39: 12.16 INR | J39: −14.58% | K39: 0.0264 | L39: Strong buy | M39: GIPCLGujarat Industries Power Co. Ltd. | N39: 146.20 INR
B40: KPELK.P. Energy Ltd. | C40: 23.6 B INR | D40: 339.05 INR | E40: −3.91% | F40: 353.62 K | G40: 1.67 | H40: 17.06 | I40: 19.87 INR | J40: 0.7168 | K40: 0.0024 | L40: Neutral | M40: KPELK.P. Energy Ltd. | N40: 339.05 INR
B41: UELUjaas Energy Limited | C41: 20.54 B INR | D41: 157.66 INR | E41: 0.0499 | F41: 2.85 K | G41: 0.16 | H41: 1554.83 | I41: 0.10 INR | J41: −81.92% | K41: 0 | L41: Neutral | M41: UELUjaas Energy Limited | N41: 157.66 INR
...

Sheet Excluded Companies
A1: Excluded Companies – Screening Rationale
A3: Company Name | B3: Screening Category | C3: Reason for Not Shortlisted
A4: Reliance Power Limited | B4: Weak Financials | C4: Persistent losses, weak balance sheet, and lack of cash flow visibility
A5: RattanIndia Power Limited | B5: High Leverage | C5: High debt levels with volatile earnings and refinancing risk
A6: Adani Power Limited | B6: Fuel & Regulatory Risk | C6: High dependence on imported coal leading to margin and regulatory risk
A7: Jaiprakash Power Ventures Limited | B7: Financial Stress | C7: Stressed balance sheet with high leverage and weak profitability
A8: Reliance Infrastructure Limited | B8: Debt & Complexity | C8: Highly leveraged structure with complex and non-transparent operations
A9: Ujaas Energy Limited | B9: Weak Profitability | C9: Consistent losses and stressed financial position
A10: Sugs Lloyd Limited | B10: Non-Core Utility | C10: EPC-focused business with limited ownership of utility assets
A11: K.P. Energy Limited | B11: EPC-Driven Model | C11: Revenue dependent on project execution rather than long-term PPAs
A12: Waaree Renewable Technologies Limited | B12: Execution & Valuation Risk | C12: Earnings volatility due to execution-heavy growth and high valuation
A13: Orient Green Power Company Limited | B13: Weak Returns | C13: Low ROE and inconsistent profitability in renewable operations
A14: Indowind Energy Limited | B14: Small Scale | C14: Low operating scale with unstable margins
... A23: SRM Energy Limited | B23: Small Scale | C23: Limited size and inconsistent operating performance
A25: Note: Companies were excluded based on financial weakness, non-core utility business models, high execution or fuel risk, limited scale, or insufficient investment visibility.
A27: Initial Screening & Remaining Remaining Companies – Preliminary Screening
A29: Screening Category | B29: Approx. Number | C29: Key Reason
A30: Very Small / Illiquid Utilities | B30: ~12 | C30: Insufficient scale for investment
A31: Early-Stage Renewable Players | B31: ~8 | C31: Execution and earnings visibility risk
A32: Holding / Mixed Businesses | B32: ~6 | C32: Non-core utility exposure
A33: Limited Disclosure Companies | B33: ~4 | C33: Insufficient public financial data
A37: Company Name | B37: Screening Category | C37: Reason for Not Shortlisted
A38: Energy Development Company Limited | B38: Regional Utility | C38: Region-specific operations with limited scale and liquidity
A39: KKV Agro Powers Limited | B39: Micro Renewable Player | C39: Very small renewable capacity and limited financial visibility
A40: Pace Digitek Limited | B40: Non-Utility Business | C40: IT and digital services company, not part of utilities sector
A41: Jayshree Chemicals Limited | B41: Non-Utility Core | C41: Chemicals manufacturing business with no meaningful utility exposure
A42: Swan Corp Limited | B42: Mixed Business Model | C42: Diversified operations where utilities are not the main value driver
A43: Nava Limited | B43: Diversified Group | C43: Power business is a small part of a diversified group
... A66: Miscellaneous Energy Firms | B66: Non-Comparable | C66: Do not fit cleanly into utility investment framework
A68: Note: These companies were screened out at a preliminary stage due to limited scale, non-core utility exposure, early-stage operations, execution-driven earnings, or insufficient investment relevance.

Sheet Raw Data
A1: Raw Financial Data – Utilities Sector
A2: Financials: FY2025 or latest available , Market Data as on: 13 / 12 / 2025
A3: Currency: INR , Amounts in ₹ Crores , Shares in Crores
A4: Sources: Annual Reports , Screener , Moneycontrol , NSE/BSE
A6: Ticker | B6: Company | C6: Share Price | D6: Market Cap | E6: Total Debt | F6: Cash & Equivalents | G6: Net Debt (formula) | H6: EBITDA | I6: EBIT | J6: Net Profit | K6: Shares Outstanding | L6: EPS (formula) | M6: Equity | N6: Book Value per Share | O6: Revenue | P6: Operating Profit | Q6: Interest Expense | R6: Dividend per Share
A7: AGNI | B7: Agni Green Power Limited | C7: 24.008065 | D7: 443.58898 | E7: 103.14324 | F7: 5.2540688 | G7: =E7-F7 -> 97.889171 | H7: 28.694836 | I7: 25.966305 | J7: 6.5947356 | K7: 19.5348 | L7: =IF(K7=0, "", J7/K7) -> 0.3375891 | M7: 125.56006 | N7: 16.950391 | O7: 432.37371 | P7: =I7 -> 25.966305 | Q7: -20.602739 | R7: =J7/K7 -> 0.3375891
A8: KKVAPOW | B8: KKV Agro Powers Limited | C8: 634.21305 | D8: 395.47116 | E8: 86.270778 | F8: 6.3035521 | G8: =E8-F8 -> 79.967226 | H8: 116.62192 | I8: 96.484586 | J8: 55.480482 | K8: 0.627163 | L8: =IF(K8=0, "", J8/K8) -> 88.46262 | M8: 131.54968 | N8: 436.45882 | O8: 8813.4166 | P8: =I8 -> 96.484586 | Q8: -8.1463958 | R8: =J8/K8 -> 88.46262
A9: 523222 | B9: SRM Energy Limited | C9: 19.27 | D9: 174.5862 | E9: 484.48792 | F9: 0.10203559 | G9: =E9-F9 -> 484.38588 | H9: -4.0399801 | I9: -4.0353054 | J9: -4.0362943 | K9: 8.88 | L9: =IF(K9=0, "", J9/K9) -> -0.45453764 | M9: -584.31468 | N9: -53.785222 | O9: 0.01 | P9: =I9 -> -4.0353054 | Q9: -0.0010787904 | R9: =J9/K9 -> -0.45453764
A10: 539013 | B10: Gita Renewable Energy Limited | C10: 94 | D10: 386.55582 | E10: 0 | F10: 0.14168114 | G10: =E10-F10 -> -0.14168114 | H10: 0.1 | I10: -4.0344963 | J10: -2.796854 | K10: 4.027272 | L10: =IF(K10=0, "", J10/K10) -> -0.69447855 | M10: 89.459503 | N10: 32.54682 | O10: 0.14168114 | P10: =I10 -> -4.0344963 | Q10: -0.10859823 | R10: =J10/K10 -> -0.69447855
A11: 538919 | B11: Skyline Ventures India Limited | C11: 41.208776 | D11: 163.46153 | E11: 11.758546 | F11: 0.042072826 | G11: =E11-F11 -> 11.716473 | H11: -6.9199909 | I11: -7.0665266 | J11: -7.0622115 | K11: 3.790909 | L11: =IF(K11=0, "", J11/K11) -> -1.8629335 | M11: 0.2804855 | N11: 10.934544 | O11: 0.01 | P11: =I11 -> -7.0665266 | Q11: -0.0010787904 | R11: =J11/K11 -> -1.8629335
A12: 541445 | B12: Waa Solar Limited | C12: 46 | D12: 610.27114 | E12: 665.54068 | F12: 242.57969 | G12: =E12-F12 -> 422.96099 | H12: 64.113323 | I12: 5.112118 | J12: 17.709333 | K12: 13.031818 | L12: =IF(K12=0, "", J12/K12) -> 1.3589304 | M12: 850.68979 | N12: 148.06713 | O12: 187.0592 | P12: =I12 -> 5.112118 | Q12: -20.384014 | R12: =J12/K12 -> 1.3589304
A13: 533451 | B13: Karma Energy Limited | C13: 55.28 | D13: 636.87165 | E13: 17.591116 | F13: 2.7981126 | G13: =E13-F13 -> 14.793003 | H13: -0.25504403 | I13: -18.481657 | J13: 5.6640092 | K13: 11.512087 | L13: =IF(K13=0, "", J13/K13) -> 0.49200542 | M13: 305.40565 | N13: 36.580924 | O13: 96.835732 | P13: =I13 -> -18.481657 | Q13: -1.7335263 | R13: =J13/K13 -> 0.49200542
A14: 532219 | B14: Energy Development Company Limited | C14: 20.12 | D14: 955.7 | E14: 1449.7719 | F14: 211.72412 | G14: =E14-F14 -> 1238.0478 | H14: 229.40739 | I14: 129.26147 | J14: -922.33819 | K14: 47.599099 | L14: =IF(K14=0, "", J14/K14) -> -19.37722 | M14: -1260.1268 | N14: 3.4351208 | O14: 423.43512 | P14: =I14 -> 129.26147 | Q14: -95.006104 | R14: =J14/K14 -> -19.37722
A15: INDOWIND | B15: Indowind Energy Limited | C15: 14.57 | D15: 1897.8845 | E15: 182.42445 | F15: 10.84535 | G15: =E15-F15 -> 171.5791 | H15: 159.79475 | I15: 80.179658 | J15: 20.044195 | K15: 128.20541 | L15: =IF(K15=0, "", J15/K15) -> 0.15634439 | M15: -102.78643 | N15: 22.570635 | O15: 399.2267 | P15: =I15 -> 80.179658 | Q15: -35.708502 | R15: =J15/K15 -> 0.15634439
A16: 543284 | B16: EKI Energy Services Limited | C16: 100.95 | D16: 2790.6309 | E16: 8.1028846 | F16: 1182.7221 | G16: =E16-F16 -> -1174.6193 | H16: -71.329981 | I16: -281.36211 | J16: -91.570516 | K16: 16.243609 | L16: =IF(K16=0, "", J16/K16) -> -5.6373258 | M16: 3662.6252 | N16: 239.73105 | O16: 1366.533 | P16: =I16 -> -281.36211 | Q16: -1.8730498 | R16: =J16/K16 -> -5.6373258
A17: 539894 | B17: Madhav Infra Projects Limited | C17: 10.75 | D17: 2898.0018 | E17: 1917.3727 | F17: 881.07599 | G17: =E17-F17 -> 1036.2967 | H17: 678.28254 | I17: 582.52551 | J17: 352.98858 | K17: 272.64348 | L17: =IF(K17=0, "", J17/K17) -> 1.2946892 | M17: 1458.0865 | N17: 8.6330717 | O17: 6577.2449 | P17: =I17 -> 582.52551 | Q17: -203.03429 | R17: =J17/K17 -> 1.2946892
A18: DPSCLTD | B18: India Power Corporation Limited | C18: 10.33 | D18: 10059.247 | E18: 1640.0129 | F18: 44.30763 | G18: =E18-F18 -> 1595.7053 | H18: 25.031353 | I18: -369.99346 | J18: 73.208425 | K18: 973.78964 | L18: =IF(K18=0, "", J18/K18) -> 0.07517889 | M18: 10362.724 | N18: 9.5076143 | O18: 6421.7705 | P18: =I18 -> -369.99346 | Q18: -249.05504 | R18: =J18/K18 -> 0.07517889
... A65: GAIL | B65: GAIL (India) Limited | C65: 168.85 | D65: 1110202.2 | E65: 226463.41 | F65: 13860.531 | G65: =E65-F65 -> 212602.88 | H65: 154178.36 | I65: 111900.84 | J65: 122023.51 | K65: 6581.1111 | L65: =IF(K65=0, "", J65/K65) -> 18.541475 | M65: 702875.55 | N65: 135.57406 | O65: 1494101.6 | P65: =I65 -> 111900.84 | Q65: -7961.77 | R65: =J65/K65 -> 18.541475

Sheet Ratios
B1: Key Financial Ratios – Utilities Sector
B2: Derived from Raw Data - Financial Year: FY2025
B3: All ratios calculated using standard formulas
B4: Conditional formatting (Green = good, Red = bad)
A7: Company | B7: EV/EBITDA | C7: P/E | D7: P/B | E7: ROE | F7: ROCE | G7: Debt/Equity | H7: Interest Coverage | I7: Operating Margin | J7: Net Profit Margin | K7: Dividend Yield | L7: Valuation Score | M7: Profitability Score | N7: Risk Score | O7: Income Score | P7: Total Score
B8: Valuation vs operating earnings → Good: 8–15 | C8: Price paid per ₹1 profit → Good: 10–25 | D8: Price vs book value → Good: 1–3 | E8: Shareholder money efficiency → Good: >15% | F8: Capital efficiency (most important) → Good: >12% | G8: Debt dependence → Good: <1.5 | H8: Ability to pay interest → Good: >3 | I8: Core business profitability → Good: Positive & stable | J8: Final profitability → Good: >8% | K8: Cash return to shareholders → Good: 1–3% (sustainable) | L8: (cheap companies score higher) | M8: (higher ROE / ROCE / margins = better) | N8: (lower leverage + higher coverage) | O8: (dividend focus for utilities) | P8: Lower Total Score = Better Company
A9: ='Raw Data'!B7 -> Agni Green Power Limited | B9: =('Raw Data'!D7+'Raw Data'!E7-'Raw Data'!F7)/'Raw Data'!H7 -> 18.87023 | C9: ='Raw Data'!C7/'Raw Data'!L7 -> 71.116232 | D9: ='Raw Data'!C7/'Raw Data'!N7 -> 1.4163724 | E9: ='Raw Data'!J7/'Raw Data'!M7 -> 0.052522561 | F9: ='Raw Data'!I7/('Raw Data'!M7+'Raw Data'!E7) -> 0.11353708 | G9: ='Raw Data'!E7/'Raw Data'!M7 -> 0.82146539 | H9: ='Raw Data'!I7/'Raw Data'!Q7 -> -1.2603327 | I9: ='Raw Data'!I7/'Raw Data'!O7 -> 0.060055236 | J9: =IFERROR('Raw Data'!J7/'Raw Data'!O7, "") -> 0.015252397 | K9: ='Raw Data'!R7/'Raw Data'!C7 -> 0.014061487 | L9: =AVERAGE(_xlfn.RANK.EQ(B9,$B$9:$B$67,1), _xlfn.RANK.EQ(C9,$C$9:$C$67,1), _xlfn.RANK.EQ(D9,$D$9:$D$67,1) ) -> 37.333333 | M9: =AVERAGE( _xlfn.RANK.EQ(E9,$E$9:$E$67,0), _xlfn.RANK.EQ(F9,$F$9:$F$67,0), _xlfn.RANK.EQ(I9,$I$9:$I$67,0), _xlfn.RANK.EQ(J9,$J$9:$J$67,0) ) -> 40 | N9: =AVERAGE( _xlfn.RANK.EQ(G9,$G$9:$G$67,1), _xlfn.RANK.EQ(H9,$H$9:$H$67,0) ) -> 28 | O9: =_xlfn.RANK.EQ(K9,$K$9:$K$67,0) -> 39 | P9: =AVERAGE(L9,M9,N9,O9) -> 36.083333
A10: ='Raw Data'!B8 -> KKV Agro Powers Limited | B10: =('Raw Data'!D8+'Raw Data'!E8-'Raw Data'!F8)/'Raw Data'!H8 -> 4.0767499 | C10: ='Raw Data'!C8/'Raw Data'!L8 -> 7.1692773 | D10: ='Raw Data'!C8/'Raw Data'!N8 -> 1.453088 | E10: ='Raw Data'!J8/'Raw Data'!M8 -> 0.42174548 | F10: ='Raw Data'!I8/('Raw Data'!M8+'Raw Data'!E8) -> 0.44295466 | G10: ='Raw Data'!E8/'Raw Data'!M8 -> 0.65580379 | H10: ='Raw Data'!I8/'Raw Data'!Q8 -> -11.843837 | I10: ='Raw Data'!I8/'Raw Data'!O8 -> 0.010947467 | J10: =IFERROR('Raw Data'!J8/'Raw Data'!O8, "") -> 0.0062950028 | K10: ='Raw Data'!R8/'Raw Data'!C8 -> 0.13948407 | L10: =AVERAGE(_xlfn.RANK.EQ(B10,$B$9:$B$67,1), _xlfn.RANK.EQ(C10,$C$9:$C$67,1), _xlfn.RANK.EQ(D10,$D$9:$D$67,1) ) -> 15.333333 | M10: =AVERAGE( _xlfn.RANK.EQ(E10,$E$9:$E$67,0), _xlfn.RANK.EQ(F10,$F$9:$F$67,0), _xlfn.RANK.EQ(I10,$I$9:$I$67,0), _xlfn.RANK.EQ(J10,$J$9:$J$67,0) ) -> 29 | N10: =AVERAGE( _xlfn.RANK.EQ(G10,$G$9:$G$67,1), _xlfn.RANK.EQ(H10,$H$9:$H$67,0) ) -> 39 | O10: =_xlfn.RANK.EQ(K10,$K$9:$K$67,0) -> 4 | P10: =AVERAGE(L10,M10,N10,O10) -> 21.833333
A11: ='Raw Data'!B9 -> SRM Energy Limited | B11: =('Raw Data'!D9+'Raw Data'!E9-'Raw Data'!F9)/'Raw Data'!H9 -> -163.1127 | C11: ='Raw Data'!C9/'Raw Data'!L9 -> -42.394728 | D11: ='Raw Data'!C9/'Raw Data'!N9 -> -0.35827685 | E11: ='Raw Data'!J9/'Raw Data'!M9 -> 0.0069077406 | F11: ='Raw Data'!I9/('Raw Data'!M9+'Raw Data'!E9) -> 0.040423079 | G11: ='Raw Data'!E9/'Raw Data'!M9 -> -0.82915581 | H11: ='Raw Data'!I9/'Raw Data'!Q9 -> 3740.5833 | I11: ='Raw Data'!I9/'Raw Data'!O9 -> -403.53054 | J11: =IFERROR('Raw Data'!J9/'Raw Data'!O9, "") -> -403.62943 | K11: ='Raw Data'!R9/'Raw Data'!C9 -> -0.023587838 | L11: =AVERAGE(_xlfn.RANK.EQ(B11,$B$9:$B$67,1), _xlfn.RANK.EQ(C11,$C$9:$C$67,1), _xlfn.RANK.EQ(D11,$D$9:$D$67,1) ) -> 3 | M11: =AVERAGE( _xlfn.RANK.EQ(E11,$E$9:$E$67,0), _xlfn.RANK.EQ(F11,$F$9:$F$67,0), _xlfn.RANK.EQ(I11,$I$9:$I$67,0), _xlfn.RANK.EQ(J11,$J$9:$J$67,0) ) -> 51.5 | N11: =AVERAGE( _xlfn.RANK.EQ(G11,$G$9:$G$67,1), _xlfn.RANK.EQ(H11,$H$9:$H$67,0) ) -> 5.5 | O11: =_xlfn.RANK.EQ(K11,$K$9:$K$67,0) -> 53 | P11: =AVERAGE(L11,M11,N11,O11) -> 28.25
A12: ='Raw Data'!B10 -> Gita Renewable Energy Limited | B12: =('Raw Data'!D10+'Raw Data'!E10-'Raw Data'!F10)/'Raw Data'!H10 -> 3864.1414 | C12: ='Raw Data'!C10/'Raw Data'!L10 -> -135.35335 | D12: ='Raw Data'!C10/'Raw Data'!N10 -> 2.888147 | E12: ='Raw Data'!J10/'Raw Data'!M10 -> -0.031263912 | F12: ='Raw Data'!I10/('Raw Data'!M10+'Raw Data'!E10) -> -0.045098577 | G12: ='Raw Data'!E10/'Raw Data'!M10 -> 0 | H12: ='Raw Data'!I10/'Raw Data'!Q10 -> 37.150662 | I12: ='Raw Data'!I10/'Raw Data'!O10 -> -28.475888 | J12: =IFERROR('Raw Data'!J10/'Raw Data'!O10, "") -> -19.740482 | K12: ='Raw Data'!R10/'Raw Data'!C10 -> -0.0073880697 | L12: =AVERAGE(_xlfn.RANK.EQ(B12,$B$9:$B$67,1), _xlfn.RANK.EQ(C12,$C$9:$C$67,1), _xlfn.RANK.EQ(D12,$D$9:$D$67,1) ) -> 33 | M12: =AVERAGE( _xlfn.RANK.EQ(E12,$E$9:$E$67,0), _xlfn.RANK.EQ(F12,$F$9:$F$67,0), _xlfn.RANK.EQ(I12,$I$9:$I$67,0), _xlfn.RANK.EQ(J12,$J$9:$J$67,0) ) -> 53.5 | N12: =AVERAGE( _xlfn.RANK.EQ(G12,$G$9:$G$67,1), _xlfn.RANK.EQ(H12,$H$9:$H$67,0) ) -> 10.5 | O12: =_xlfn.RANK.EQ(K12,$K$9:$K$67,0) -> 50 | P12: =AVERAGE(L12,M12,N12,O12) -> 36.75
A13: ='Raw Data'!B11 -> Skyline Ventures India Limited | B13: =('Raw Data'!D11+'Raw Data'!E11-'Raw Data'!F11)/'Raw Data'!H11 -> -25.314774 | C13: ='Raw Data'!C11/'Raw Data'!L11 -> -22.120368 | D13: ='Raw Data'!C11/'Raw Data'!N11 -> 3.7686782 | E13: ='Raw Data'!J11/'Raw Data'!M11 -> -25.178526 | F13: ='Raw Data'!I11/('Raw Data'!M11+'Raw Data'!E11) -> -0.58696805 | G13: ='Raw Data'!E11/'Raw Data'!M11 -> 41.922115 | H13: ='Raw Data'!I11/'Raw Data'!Q11 -> 6550.4167 | I13: ='Raw Data'!I11/'Raw Data'!O11 -> -706.65266 | J13: =IFERROR('Raw Data'!J11/'Raw Data'!O11, "") -> -706.22115 | K13: ='Raw Data'!R11/'Raw Data'!C11 -> -0.045207204 | L13: =AVERAGE(_xlfn.RANK.EQ(B13,$B$9:$B$67,1), _xlfn.RANK.EQ(C13,$C$9:$C$67,1), _xlfn.RANK.EQ(D13,$D$9:$D$67,1) ) -> 19.333333 | M13: =AVERAGE( _xlfn.RANK.EQ(E13,$E$9:$E$67,0), _xlfn.RANK.EQ(F13,$F$9:$F$67,0), _xlfn.RANK.EQ(I13,$I$9:$I$67,0), _xlfn.RANK.EQ(J13,$J$9:$J$67,0) ) -> 59 | N13: =AVERAGE( _xlfn.RANK.EQ(G13,$G$9:$G$67,1), _xlfn.RANK.EQ(H13,$H$9:$H$67,0) ) -> 30 | O13: =_xlfn.RANK.EQ(K13,$K$9:$K$67,0) -> 54 | P13: =AVERAGE(L13,M13,N13,O13) -> 40.583333
A14: ='Raw Data'!B12 -> Waa Solar Limited | B14: =('Raw Data'!D12+'Raw Data'!E12-'Raw Data'!F12)/'Raw Data'!H12 -> 16.115717 | C14: ='Raw Data'!C12/'Raw Data'!L12 -> 33.850152 | D14: ='Raw Data'!C12/'Raw Data'!N12 -> 0.31066989 | E14: ='Raw Data'!J12/'Raw Data'!M12 -> 0.020817616 | F14: ='Raw Data'!I12/('Raw Data'!M12+'Raw Data'!E12) -> 0.0033715969 | G14: ='Raw Data'!E12/'Raw Data'!M12 -> 0.78235414 | H14: ='Raw Data'!I12/'Raw Data'!Q12 -> -0.25079054 | I14: ='Raw Data'!I12/'Raw Data'!O12 -> 0.027328878 | J14: =IFERROR('Raw Data'!J12/'Raw Data'!O12, "") -> 0.094672347 | K14: ='Raw Data'!R12/'Raw Data'!C12 -> 0.029541965 | L14: =AVERAGE(_xlfn.RANK.EQ(B14,$B$9:$B$67,1), _xlfn.RANK.EQ(C14,$C$9:$C$67,1), _xlfn.RANK.EQ(D14,$D$9:$D$67,1) ) -> 29.333333 | M14: =AVERAGE( _xlfn.RANK.EQ(E14,$E$9:$E$67,0), _xlfn.RANK.EQ(F14,$F$9:$F$67,0), _xlfn.RANK.EQ(I14,$I$9:$I$67,0), _xlfn.RANK.EQ(J14,$J$9:$J$67,0) ) -> 41 | N14: =AVERAGE( _xlfn.RANK.EQ(G14,$G$9:$G$67,1), _xlfn.RANK.EQ(H14,$H$9:$H$67,0) ) -> 25.5 | O14: =_xlfn.RANK.EQ(K14,$K$9:$K$67,0) -> 34 | P14: =AVERAGE(L14,M14,N14,O14) -> 32.458333
A15: ='Raw Data'!B13 -> Karma Energy Limited | B15: =('Raw Data'!D13+'Raw Data'!E13-'Raw Data'!F13)/'Raw Data'!H13 -> -2555.1065 | C15: ='Raw Data'!C13/'Raw Data'!L13 -> 112.35649 | D15: ='Raw Data'!C13/'Raw Data'!N13 -> 1.5111702 | E15: ='Raw Data'!J13/'Raw Data'!M13 -> 0.018545856 | F15: ='Raw Data'!I13/('Raw Data'!M13+'Raw Data'!E13) -> -0.057219326 | G15: ='Raw Data'!E13/'Raw Data'!M13 -> 0.057599182 | H15: ='Raw Data'!I13/'Raw Data'!Q13 -> 10.661308 | I15: ='Raw Data'!I13/'Raw Data'!O13 -> -0.19085576 | J15: =IFERROR('Raw Data'!J13/'Raw Data'!O13, "") -> 0.058490901 | K15: ='Raw Data'!R13/'Raw Data'!C13 -> 0.0089002428 | L15: =AVERAGE(_xlfn.RANK.EQ(B15,$B$9:$B$67,1), _xlfn.RANK.EQ(C15,$C$9:$C$67,1), _xlfn.RANK.EQ(D15,$D$9:$D$67,1) ) -> 25.333333 | M15: =AVERAGE( _xlfn.RANK.EQ(E15,$E$9:$E$67,0), _xlfn.RANK.EQ(F15,$F$9:$F$67,0), _xlfn.RANK.EQ(I15,$I$9:$I$67,0), _xlfn.RANK.EQ(J15,$J$9:$J$67,0) ) -> 47.25 | N15: =AVERAGE( _xlfn.RANK.EQ(G15,$G$9:$G$67,1), _xlfn.RANK.EQ(H15,$H$9:$H$67,0) ) -> 16 | O15: =_xlfn.RANK.EQ(K15,$K$9:$K$67,0) -> 44 | P15: =AVERAGE(L15,M15,N15,O15) -> 33.145833
A16: ='Raw Data'!B14 -> Energy Development Company Limited | B16: =('Raw Data'!D14+'Raw Data'!E14-'Raw Data'!F14)/'Raw Data'!H14 -> 9.562673 | C16: ='Raw Data'!C14/'Raw Data'!L14 -> -1.0383327 | D16: ='Raw Data'!C14/'Raw Data'!N14 -> 5.8571448 | E16: ='Raw Data'!J14/'Raw Data'!M14 -> 0.73194078 | F16: ='Raw Data'!I14/('Raw Data'!M14+'Raw Data'!E14) -> 0.68159653 | G16: ='Raw Data'!E14/'Raw Data'!M14 -> -1.1504969 | H16: ='Raw Data'!I14/'Raw Data'!Q14 -> -1.3605597 | I16: ='Raw Data'!I14/'Raw Data'!O14 -> 0.30526867 | J16: =IFERROR('Raw Data'!J14/'Raw Data'!O14, "") -> -2.1782279 | K16: ='Raw Data'!R14/'Raw Data'!C14 -> -0.96308248 | L16: =AVERAGE(_xlfn.RANK.EQ(B16,$B$9:$B$67,1), _xlfn.RANK.EQ(C16,$C$9:$C$67,1), _xlfn.RANK.EQ(D16,$D$9:$D$67,1) ) -> 28.333333 | M16: =AVERAGE( _xlfn.RANK.EQ(E16,$E$9:$E$67,0), _xlfn.RANK.EQ(F16,$F$9:$F$67,0), _xlfn.RANK.EQ(I16,$I$9:$I$67,0), _xlfn.RANK.EQ(J16,$J$9:$J$67,0) ) -> 18.5 | N16: =AVERAGE( _xlfn.RANK.EQ(G16,$G$9:$G$67,1), _xlfn.RANK.EQ(H16,$H$9:$H$67,0) ) -> 12.5 | O16: =_xlfn.RANK.EQ(K16,$K$9:$K$67,0) -> 59 | P16: =AVERAGE(L16,M16,N16,O16) -> 29.583333
A17: ='Raw Data'!B15 -> Indowind Energy Limited | B17: =('Raw Data'!D15+'Raw Data'!E15-'Raw Data'!F15)/'Raw Data'!H15 -> 12.950761 | C17: ='Raw Data'!C15/'Raw Data'!L15 -> 93.191706 | D17: ='Raw Data'!C15/'Raw Data'!N15 -> 0.64552903 | E17: ='Raw Data'!J15/'Raw Data'!M15 -> -0.19500819 | F17: ='Raw Data'!I15/('Raw Data'!M15+'Raw Data'!E15) -> 1.0068013 | G17: ='Raw Data'!E15/'Raw Data'!M15 -> -1.7747911 | H17: ='Raw Data'!I15/'Raw Data'!Q15 -> -2.2453941 | I17: ='Raw Data'!I15/'Raw Data'!O15 -> 0.20083741 | J17: =IFERROR('Raw Data'!J15/'Raw Data'!O15, "") -> 0.050207551 | K17: ='Raw Data'!R15/'Raw Data'!C15 -> 0.010730569 | L17: =AVERAGE(_xlfn.RANK.EQ(B17,$B$9:$B$67,1), _xlfn.RANK.EQ(C17,$C$9:$C$67,1), _xlfn.RANK.EQ(D17,$D$9:$D$67,1) ) -> 31.666667 | M17: =AVERAGE( _xlfn.RANK.EQ(E17,$E$9:$E$67,0), _xlfn.RANK.EQ(F17,$F$9:$F$67,0), _xlfn.RANK.EQ(I17,$I$9:$I$67,0), _xlfn.RANK.EQ(J17,$J$9:$J$67,0) ) -> 29 | N17: =AVERAGE( _xlfn.RANK.EQ(G17,$G$9:$G$67,1), _xlfn.RANK.EQ(H17,$H$9:$H$67,0) ) -> 16 | O17: =_xlfn.RANK.EQ(K17,$K$9:$K$67,0) -> 42 | P17: =AVERAGE(L17,M17,N17,O17) -> 29.666667
A18: ='Raw Data'!B16 -> EKI Energy Services Limited | B18: =('Raw Data'!D16+'Raw Data'!E16-'Raw Data'!F16)/'Raw Data'!H16 -> -22.655434 | C18: ='Raw Data'!C16/'Raw Data'!L16 -> -17.907427 | D18: ='Raw Data'!C16/'Raw Data'!N16 -> 0.42109689 | E18: ='Raw Data'!J16/'Raw Data'!M16 -> -0.025001334 | F18: ='Raw Data'!I16/('Raw Data'!M16+'Raw Data'!E16) -> -0.076650219 | G18: ='Raw Data'!E16/'Raw Data'!M16 -> 0.0022123161 | H18: ='Raw Data'!I16/'Raw Data'!Q16 -> 150.21603 | I18: ='Raw Data'!I16/'Raw Data'!O16 -> -0.20589485 | J18: =IFERROR('Raw Data'!J16/'Raw Data'!O16, "") -> -0.06700937 | K18: ='Raw Data'!R16/'Raw Data'!C16 -> -0.055842752 | L18: =AVERAGE(_xlfn.RANK.EQ(B18,$B$9:$B$67,1), _xlfn.RANK.EQ(C18,$C$9:$C$67,1), _xlfn.RANK.EQ(D18,$D$9:$D$67,1) ) -> 5.6666667 | M18: =AVERAGE( _xlfn.RANK.EQ(E18,$E$9:$E$67,0), _xlfn.RANK.EQ(F18,$F$9:$F$67,0), _xlfn.RANK.EQ(I18,$I$9:$I$67,0), _xlfn.RANK.EQ(J18,$J$9:$J$67,0) ) -> 51.5 | N18: =AVERAGE( _xlfn.RANK.EQ(G18,$G$9:$G$67,1), _xlfn.RANK.EQ(H18,$H$9:$H$67,0) ) -> 10 | O18: =_xlfn.RANK.EQ(K18,$K$9:$K$67,0) -> 55 | P18: =AVERAGE(L18,M18,N18,O18) -> 30.541667
A19: ='Raw Data'!B17 -> Madhav Infra Projects Limited | B19: =('Raw Data'!D17+'Raw Data'!E17-'Raw Data'!F17)/'Raw Data'!H17 -> 5.8003829 | C19: ='Raw Data'!C17/'Raw Data'!L17 -> 8.3031507 | D19: ='Raw Data'!C17/'Raw Data'!N17 -> 1.2452115 | E19: ='Raw Data'!J17/'Raw Data'!M17 -> 0.2420903 | F19: ='Raw Data'!I17/('Raw Data'!M17+'Raw Data'!E17) -> 0.17257668 | G19: ='Raw Data'!E17/'Raw Data'!M17 -> 1.3149924 | H19: ='Raw Data'!I17/'Raw Data'!Q17 -> -2.8690992 | I19: ='Raw Data'!I17/'Raw Data'!O17 -> 0.088566796 | J19: =IFERROR('Raw Data'!J17/'Raw Data'!O17, "") -> 0.053668152 | K19: ='Raw Data'!R17/'Raw Data'!C17 -> 0.12043621 | L19: =AVERAGE(_xlfn.RANK.EQ(B19,$B$9:$B$67,1), _xlfn.RANK.EQ(C19,$C$9:$C$67,1), _xlfn.RANK.EQ(D19,$D$9:$D$67,1) ) -> 14.666667 | M19: =AVERAGE( _xlfn.RANK.EQ(E19,$E$9:$E$67,0), _xlfn.RANK.EQ(F19,$F$9:$F$67,0), _xlfn.RANK.EQ(I19,$I$9:$I$67,0), _xlfn.RANK.EQ(J19,$J$9:$J$67,0) ) -> 28.5 | N19: =AVERAGE( _xlfn.RANK.EQ(G19,$G$9:$G$67,1), _xlfn.RANK.EQ(H19,$H$9:$H$67,0) ) -> 37 | O19: =_xlfn.RANK.EQ(K19,$K$9:$K$67,0) -> 5 | P19: =AVERAGE(L19,M19,N19,O19) -> 21.291667
A20: ='Raw Data'!B18 -> India Power Corporation Limited | B20: =('Raw Data'!D18+'Raw Data'!E18-'Raw Data'!F18)/'Raw Data'!H18 -> 465.61415 | C20: ='Raw Data'!C18/'Raw Data'!L18 -> 137.40559 | D20: ='Raw Data'!C18/'Raw Data'!N18 -> 1.0864976 | E20: ='Raw Data'!J18/'Raw Data'!M18 -> 0.0070645929 | F20: ='Raw Data'!I18/('Raw Data'!M18+'Raw Data'!E18) -> -0.030825758 | G20: ='Raw Data'!E18/'Raw Data'!M18 -> 0.1582608 | H20: ='Raw Data'!I18/'Raw Data'!Q18 -> 1.4855892 | I20: ='Raw Data'!I18/'Raw Data'!O18 -> -0.057615491 | J20: =IFERROR('Raw Data'!J18/'Raw Data'!O18, "") -> 0.011400037 | K20: ='Raw Data'!R18/'Raw Data'!C18 -> 0.0072777241 | L20: =AVERAGE(_xlfn.RANK.EQ(B20,$B$9:$B$67,1), _xlfn.RANK.EQ(C20,$C$9:$C$67,1), _xlfn.RANK.EQ(D20,$D$9:$D$67,1) ) -> 42 | M20: =AVERAGE( _xlfn.RANK.EQ(E20,$E$9:$E$67,0), _xlfn.RANK.EQ(F20,$F$9:$F$67,0), _xlfn.RANK.EQ(I20,$I$9:$I$67,0), _xlfn.RANK.EQ(J20,$J$9:$J$67,0) ) -> 48 | N20: =AVERAGE( _xlfn.RANK.EQ(G20,$G$9:$G$67,1), _xlfn.RANK.EQ(H20,$H$9:$H$67,0) ) -> 20 | O20: =_xlfn.RANK.EQ(K20,$K$9:$K$67,0) -> 47 | P20: =AVERAGE(L20,M20,N20,O20) -> 39.25
... A67: ='Raw Data'!B65 -> GAIL (India) Limited | B67: =('Raw Data'!D65+'Raw Data'!E65-'Raw Data'!F65)/'Raw Data'!H65 -> 8.5797064 | C67: ='Raw Data'!C65/'Raw Data'!L65 -> 9.1066108 | D67: ='Raw Data'!C65/'Raw Data'!N65 -> 1.2454448 | E67: ='Raw Data'!J65/'Raw Data'!M65 -> 0.17360614 | F67: ='Raw Data'!I65/('Raw Data'!M65+'Raw Data'!E65) -> 0.12040907 | G67: ='Raw Data'!E65/'Raw Data'!M65 -> 0.3221956 | H67: ='Raw Data'!I65/'Raw Data'!Q65 -> -14.054769 | I67: ='Raw Data'!I65/'Raw Data'!O65 -> 0.07489507 | J67: =IFERROR('Raw Data'!J65/'Raw Data'!O65, "") -> 0.081670157 | K67: ='Raw Data'!R65/'Raw Data'!C65 -> 0.10981034 | L67: =AVERAGE(_xlfn.RANK.EQ(B67,$B$9:$B$67,1), _xlfn.RANK.EQ(C67,$C$9:$C$67,1), _xlfn.RANK.EQ(D67,$D$9:$D$67,1) ) -> 17.333333 | M67: =AVERAGE( _xlfn.RANK.EQ(E67,$E$9:$E$67,0), _xlfn.RANK.EQ(F67,$F$9:$F$67,0), _xlfn.RANK.EQ(I67,$I$9:$I$67,0), _xlfn.RANK.EQ(J67,$J$9:$J$67,0) ) -> 31.75 | N67: =AVERAGE( _xlfn.RANK.EQ(G67,$G$9:$G$67,1), _xlfn.RANK.EQ(H67,$H$9:$H$67,0) ) -> 38.5 | O67: =_xlfn.RANK.EQ(K67,$K$9:$K$67,0) -> 7 | P67: =AVERAGE(L67,M67,N67,O67) -> 23.645833

Sheet Selecting on the basis of Ratio
A5: Company | B5: Filtering as per Column C to L | C5: EV/EBITDA | D5: P/E | E5: P/B | F5: ROE | G5: ROCE | H5: Debt/Equity | I5: Interest Coverage | J5: Operating Margin | K5: Net Profit Margin | L5: Dividend Yield | M5: Valuation Score | N5: Profitability Score | O5: Risk Score | P5: Income Score | Q5: Total Score | R5: Selection (Rank)
A6: ='Raw Data'!B41 -> Adani Power Limited | B6: =COUNTIF($C$69:$L$98,A6) -> 6 | C6: =('Raw Data'!D41+'Raw Data'!E41-'Raw Data'!F41)/'Raw Data'!H41 -> 14.747371 | D6: ='Raw Data'!C41/'Raw Data'!L41 -> 22.265673 | E6: ='Raw Data'!C41/'Raw Data'!N41 -> 4.5832997 | F6: ='Raw Data'!J41/'Raw Data'!M41 -> 0.36392917 | G6: ='Raw Data'!I41/('Raw Data'!M41+'Raw Data'!E41) -> 0.19976001 | H6: ='Raw Data'!E41/'Raw Data'!M41 -> 1.4658921 | I6: ='Raw Data'!I41/'Raw Data'!Q41 -> -5.1653446 | J6: ='Raw Data'!I41/'Raw Data'!O41 -> 0.29356424 | K6: =IFERROR('Raw Data'!J41/'Raw Data'!O41, "") -> 0.21688893 | L6: ='Raw Data'!R41/'Raw Data'!C41 -> 0.044912184 | M6: =AVERAGE(_xlfn.RANK.EQ(C6,$C$6:$C$64,1), _xlfn.RANK.EQ(D6,$D$6:$D$64,1), _xlfn.RANK.EQ(E6,$E$6:$E$64,1) ) -> 42 | N6: =AVERAGE( _xlfn.RANK.EQ(F6,$F$6:$F$64,0), _xlfn.RANK.EQ(G6,$G$6:$G$64,0), _xlfn.RANK.EQ(J6,$J$6:$J$64,0), _xlfn.RANK.EQ(K6,$K$6:$K$64,0) ) -> 12.75 | O6: =AVERAGE( _xlfn.RANK.EQ(H6,$H$6:$H$64,1), _xlfn.RANK.EQ(I6,$I$6:$I$64,0) ) -> 41.5 | P6: =_xlfn.RANK.EQ(L6,$L$6:$L$64,0) -> 26 | Q6: =AVERAGE(M6,N6,O6,P6) -> 30.5625 | R6: =IF(Q6<=20,"Excellent",IF(Q6<=25,"Very Good",IF(Q6<=30,"Decent",IF(Q6<=35,"Average","Weak/Avoid")))) -> Average
A7: ='Raw Data'!B47 -> K.P. Energy Limited | B7: =COUNTIF($C$69:$L$98,A7) -> 6 | C7: =('Raw Data'!D47+'Raw Data'!E47-'Raw Data'!F47)/'Raw Data'!H47 -> 11.766423 | D7: ='Raw Data'!C47/'Raw Data'!L47 -> 16.99577 | E7: ='Raw Data'!C47/'Raw Data'!N47 -> 6.0149248 | F7: ='Raw Data'!J47/'Raw Data'!M47 -> 0.39651643 | G7: ='Raw Data'!I47/('Raw Data'!M47+'Raw Data'!E47) -> 0.26428625 | H7: ='Raw Data'!E47/'Raw Data'!M47 -> 1.3621101 | I7: ='Raw Data'!I47/'Raw Data'!Q47 -> -581.32448 | J7: ='Raw Data'!I47/'Raw Data'!O47 -> 0.18554535 | K7: =IFERROR('Raw Data'!J47/'Raw Data'!O47, "") -> 0.11785189 | L7: ='Raw Data'!R47/'Raw Data'!C47 -> 0.05883817 | M7: =AVERAGE(_xlfn.RANK.EQ(C7,$C$6:$C$64,1), _xlfn.RANK.EQ(D7,$D$6:$D$64,1), _xlfn.RANK.EQ(E7,$E$6:$E$64,1) ) -> 38.666667 | N7: =AVERAGE( _xlfn.RANK.EQ(F7,$F$6:$F$64,0), _xlfn.RANK.EQ(G7,$G$6:$G$64,0), _xlfn.RANK.EQ(J7,$J$6:$J$64,0), _xlfn.RANK.EQ(K7,$K$6:$K$64,0) ) -> 17 | O7: =AVERAGE( _xlfn.RANK.EQ(H7,$H$6:$H$64,1), _xlfn.RANK.EQ(I7,$I$6:$I$64,0) ) -> 50 | P7: =_xlfn.RANK.EQ(L7,$L$6:$L$64,0) -> 20 | Q7: =AVERAGE(M7,N7,O7,P7) -> 31.416667 | R7: =IF(Q7<=20,"Excellent",IF(Q7<=25,"Very Good",IF(Q7<=30,"Decent",IF(Q7<=35,"Average","Weak/Avoid")))) -> Average
A8: ='Raw Data'!B34 -> Torrent Power Limited | B8: =COUNTIF($C$69:$L$98,A8) -> 6 | C8: =('Raw Data'!D34+'Raw Data'!E34-'Raw Data'!F34)/'Raw Data'!H34 -> 13.996731 | D8: ='Raw Data'!C34/'Raw Data'!L34 -> 22.416167 | E8: ='Raw Data'!C34/'Raw Data'!N34 -> 3.4976448 | F8: ='Raw Data'!J34/'Raw Data'!M34 -> 0.20058306 | G8: ='Raw Data'!I34/('Raw Data'!M34+'Raw Data'!E34) -> 0.15575351 | H8: ='Raw Data'!E34/'Raw Data'!M34 -> 0.6453041 | I8: ='Raw Data'!I34/'Raw Data'!Q34 -> -3.6408347 | J8: ='Raw Data'!I34/'Raw Data'!O34 -> 0.12520267 | K8: =IFERROR('Raw Data'!J34/'Raw Data'!O34, "") -> 0.097999494 | L8: ='Raw Data'!R34/'Raw Data'!C34 -> 0.044610659 | M8: =AVERAGE(_xlfn.RANK.EQ(C8,$C$6:$C$64,1), _xlfn.RANK.EQ(D8,$D$6:$D$64,1), _xlfn.RANK.EQ(E8,$E$6:$E$64,1) ) -> 39.666667 | N8: =AVERAGE( _xlfn.RANK.EQ(F8,$F$6:$F$64,0), _xlfn.RANK.EQ(G8,$G$6:$G$64,0), _xlfn.RANK.EQ(J8,$J$6:$J$64,0), _xlfn.RANK.EQ(K8,$K$6:$K$64,0) ) -> 25.75 | O8: =AVERAGE( _xlfn.RANK.EQ(H8,$H$6:$H$64,1), _xlfn.RANK.EQ(I8,$I$6:$I$64,0) ) -> 35 | P8: =_xlfn.RANK.EQ(L8,$L$6:$L$64,0) -> 27 | Q8: =AVERAGE(M8,N8,O8,P8) -> 31.854167 | R8: =IF(Q8<=20,"Excellent",IF(Q8<=25,"Very Good",IF(Q8<=30,"Decent",IF(Q8<=35,"Average","Weak/Avoid")))) -> Average
A9: ='Raw Data'!B51 -> Waaree Renewable Technologies Limited | B9: =COUNTIF($C$69:$L$98,A9) -> 5 | C9: =('Raw Data'!D51+'Raw Data'!E51-'Raw Data'!F51)/'Raw Data'!H51 -> 29.577114 | D9: ='Raw Data'!C51/'Raw Data'!L51 -> 40.848806 | E9: ='Raw Data'!C51/'Raw Data'!N51 -> 20.55474 | F9: ='Raw Data'!J51/'Raw Data'!M51 -> 1.1167919 | G9: ='Raw Data'!I51/('Raw Data'!M51+'Raw Data'!E51) -> 1.3094245 | H9: ='Raw Data'!E51/'Raw Data'!M51 -> 0.13339702 | I9: ='Raw Data'!I51/'Raw Data'!Q51 -> -19.692367 | J9: ='Raw Data'!I51/'Raw Data'!O51 -> 0.19059985 | K9: =IFERROR('Raw Data'!J51/'Raw Data'!O51, "") -> 0.14342745 | L9: ='Raw Data'!R51/'Raw Data'!C51 -> 0.02448052 | M9: =AVERAGE(_xlfn.RANK.EQ(C9,$C$6:$C$64,1), _xlfn.RANK.EQ(D9,$D$6:$D$64,1), _xlfn.RANK.EQ(E9,$E$6:$E$64,1) ) -> 51.333333 | N9: =AVERAGE( _xlfn.RANK.EQ(F9,$F$6:$F$64,0), _xlfn.RANK.EQ(G9,$G$6:$G$64,0), _xlfn.RANK.EQ(J9,$J$6:$J$64,0), _xlfn.RANK.EQ(K9,$K$6:$K$64,0) ) -> 9.75 | O9: =AVERAGE( _xlfn.RANK.EQ(H9,$H$6:$H$64,1), _xlfn.RANK.EQ(I9,$I$6:$I$64,0) ) -> 36.5 | P9: =_xlfn.RANK.EQ(L9,$L$6:$L$64,0) -> 37 | Q9: =AVERAGE(M9,N9,O9,P9) -> 33.645833 | R9: =IF(Q9<=20,"Excellent",IF(Q9<=25,"Very Good",IF(Q9<=30,"Decent",IF(Q9<=35,"Average","Weak/Avoid")))) -> Average
A10: ='Raw Data'!B55 -> Apex Ecotech Limited | B10: =COUNTIF($C$69:$L$98,A10) -> 6 | C10: =('Raw Data'!D55+'Raw Data'!E55-'Raw Data'!F55)/'Raw Data'!H55 -> 12.887644 | D10: ='Raw Data'!C55/'Raw Data'!L55 -> 18.667193 | E10: ='Raw Data'!C55/'Raw Data'!N55 -> 3.6659147 | F10: ='Raw Data'!J55/'Raw Data'!M55 -> 0.7210143 | G10: ='Raw Data'!I55/('Raw Data'!M55+'Raw Data'!E55) -> 0.91387203 | H10: ='Raw Data'!E55/'Raw Data'!M55 -> 0.0060171447 | I10: ='Raw Data'!I55/'Raw Data'!Q55 -> -174.21338 | J10: ='Raw Data'!I55/'Raw Data'!O55 -> 0.14937874 | K10: =IFERROR('Raw Data'!J55/'Raw Data'!O55, "") -> 0.1171499 | L10: ='Raw Data'!R55/'Raw Data'!C55 -> 0.053569917 | M10: =AVERAGE(_xlfn.RANK.EQ(C10,$C$6:$C$64,1), _xlfn.RANK.EQ(D10,$D$6:$D$64,1), _xlfn.RANK.EQ(E10,$E$6:$E$64,1) ) -> 38.333333 | N10: =AVERAGE( _xlfn.RANK.EQ(F10,$F$6:$F$64,0), _xlfn.RANK.EQ(G10,$G$6:$G$64,0), _xlfn.RANK.EQ(J10,$J$6:$J$64,0), _xlfn.RANK.EQ(K10,$K$6:$K$64,0) ) -> 15.25 | O10: =AVERAGE( _xlfn.RANK.EQ(H10,$H$6:$H$64,1), _xlfn.RANK.EQ(I10,$I$6:$I$64,0) ) -> 35 | P10: =_xlfn.RANK.EQ(L10,$L$6:$L$64,0) -> 23 | Q10: =AVERAGE(M10,N10,O10,P10) -> 27.895833 | R10: =IF(Q10<=20,"Excellent",IF(Q10<=25,"Very Good",IF(Q10<=30,"Decent",IF(Q10<=35,"Average","Weak/Avoid")))) -> Decent
A11: ='Raw Data'!B61 -> Indraprastha Gas Limited | B11: =COUNTIF($C$69:$L$98,A11) -> 7 | C11: =('Raw Data'!D61+'Raw Data'!E61-'Raw Data'!F61)/'Raw Data'!H61 -> 12.748116 | D11: ='Raw Data'!C61/'Raw Data'!L61 -> 14.756108 | E11: ='Raw Data'!C61/'Raw Data'!N61 -> 2.3152273 | F11: ='Raw Data'!J61/'Raw Data'!M61 -> 0.16059533 | G11: ='Raw Data'!I61/('Raw Data'!M61+'Raw Data'!E61) -> 0.1358562 | H11: ='Raw Data'!E61/'Raw Data'!M61 -> 0.00901415 | I11: ='Raw Data'!I61/'Raw Data'!Q61 -> -181.31095 | J11: ='Raw Data'!I61/'Raw Data'!O61 -> 0.092771033 | K11: =IFERROR('Raw Data'!J61/'Raw Data'!O61, "") -> 0.10868474 | L11: ='Raw Data'!R61/'Raw Data'!C61 -> 0.067768549 | M11: =AVERAGE(_xlfn.RANK.EQ(C11,$C$6:$C$64,1), _xlfn.RANK.EQ(D11,$D$6:$D$64,1), _xlfn.RANK.EQ(E11,$E$6:$E$64,1) ) -> 30.333333 | N11: =AVERAGE( _xlfn.RANK.EQ(F11,$F$6:$F$64,0), _xlfn.RANK.EQ(G11,$G$6:$G$64,0), _xlfn.RANK.EQ(J11,$J$6:$J$64,0), _xlfn.RANK.EQ(K11,$K$6:$K$64,0) ) -> 29.25 | O11: =AVERAGE( _xlfn.RANK.EQ(H11,$H$6:$H$64,1), _xlfn.RANK.EQ(I11,$I$6:$I$64,0) ) -> 36 | P11: =_xlfn.RANK.EQ(L11,$L$6:$L$64,0) -> 14 | Q11: =AVERAGE(M11,N11,O11,P11) -> 27.395833 | R11: =IF(Q11<=20,"Excellent",IF(Q11<=25,"Very Good",IF(Q11<=30,"Decent",IF(Q11<=35,"Average","Weak/Avoid")))) -> Decent
A12: ='Raw Data'!B50 -> KPI Green Energy Limited | B12: =COUNTIF($C$69:$L$98,A12) -> 6 | C12: =('Raw Data'!D50+'Raw Data'!E50-'Raw Data'!F50)/'Raw Data'!H50 -> 14.083948 | D12: ='Raw Data'!C50/'Raw Data'!L50 -> 22.050734 | E12: ='Raw Data'!C50/'Raw Data'!N50 -> 2.8761563 | F12: ='Raw Data'!J50/'Raw Data'!M50 -> 0.55499477 | G12: ='Raw Data'!I50/('Raw Data'!M50+'Raw Data'!E50) -> 0.2635707 | H12: ='Raw Data'!E50/'Raw Data'!M50 -> 2.2439262 | I12: ='Raw Data'!I50/'Raw Data'!Q50 -> -6.1756095 | J12: ='Raw Data'!I50/'Raw Data'!O50 -> 0.28234295 | K12: =IFERROR('Raw Data'!J50/'Raw Data'!O50, "") -> 0.18327269 | L12: ='Raw Data'!R50/'Raw Data'!C50 -> 0.045349964 | M12: =AVERAGE(_xlfn.RANK.EQ(C12,$C$6:$C$64,1), _xlfn.RANK.EQ(D12,$D$6:$D$64,1), _xlfn.RANK.EQ(E12,$E$6:$E$64,1) ) -> 37.666667 | N12: =AVERAGE( _xlfn.RANK.EQ(F12,$F$6:$F$64,0), _xlfn.RANK.EQ(G12,$G$6:$G$64,0), _xlfn.RANK.EQ(J12,$J$6:$J$64,0), _xlfn.RANK.EQ(K12,$K$6:$K$64,0) ) -> 11.75 | O12: =AVERAGE( _xlfn.RANK.EQ(H12,$H$6:$H$64,1), _xlfn.RANK.EQ(I12,$I$6:$I$64,0) ) -> 45.5 | P12: =_xlfn.RANK.EQ(L12,$L$6:$L$64,0) -> 25 | Q12: =AVERAGE(M12,N12,O12,P12) -> 29.979167 | R12: =IF(Q12<=20,"Excellent",IF(Q12<=25,"Very Good",IF(Q12<=30,"Decent",IF(Q12<=35,"Average","Weak/Avoid")))) -> Decent
A13: ='Raw Data'!B30 -> Nava Limited | B13: =COUNTIF($C$69:$L$98,A13) -> 6 | C13: =('Raw Data'!D30+'Raw Data'!E30-'Raw Data'!F30)/'Raw Data'!H30 -> 9.0896363 | D13: ='Raw Data'!C30/'Raw Data'!L30 -> 17.218832 | E13: ='Raw Data'!C30/'Raw Data'!N30 -> 1.9600105 | F13: ='Raw Data'!J30/'Raw Data'!M30 -> 0.13094144 | G13: ='Raw Data'!I30/('Raw Data'!M30+'Raw Data'!E30) -> 0.15830571 | H13: ='Raw Data'!E30/'Raw Data'!M30 -> 0.22656686 | I13: ='Raw Data'!I30/'Raw Data'!Q30 -> -242.69039 | J13: ='Raw Data'!I30/'Raw Data'!O30 -> 0.34040571 | K13: =IFERROR('Raw Data'!J30/'Raw Data'!O30, "") -> 0.22955467 | L13: ='Raw Data'!R30/'Raw Data'!C30 -> 0.058075947 | M13: =AVERAGE(_xlfn.RANK.EQ(C13,$C$6:$C$64,1), _xlfn.RANK.EQ(D13,$D$6:$D$64,1), _xlfn.RANK.EQ(E13,$E$6:$E$64,1) ) -> 28 | N13: =AVERAGE( _xlfn.RANK.EQ(F13,$F$6:$F$64,0), _xlfn.RANK.EQ(G13,$G$6:$G$64,0), _xlfn.RANK.EQ(J13,$J$6:$J$64,0), _xlfn.RANK.EQ(K13,$K$6:$K$64,0) ) -> 18 | O13: =AVERAGE( _xlfn.RANK.EQ(H13,$H$6:$H$64,1), _xlfn.RANK.EQ(I13,$I$6:$I$64,0) ) -> 43.5 | P13: =_xlfn.RANK.EQ(L13,$L$6:$L$64,0) -> 21 | Q13: =AVERAGE(M13,N13,O13,P13) -> 27.625 | R13: =IF(Q13<=20,"Excellent",IF(Q13<=25,"Very Good",IF(Q13<=30,"Decent",IF(Q13<=35,"Average","Weak/Avoid")))) -> Decent
A14: ='Raw Data'!B42 -> NTPC Limited | B14: =COUNTIF($C$69:$L$98,A14) -> 5 | C14: =('Raw Data'!D42+'Raw Data'!E42-'Raw Data'!F42)/'Raw Data'!H42 -> 10.228818 | D14: ='Raw Data'!C42/'Raw Data'!L42 -> 13.002939 | E14: ='Raw Data'!C42/'Raw Data'!N42 -> 1.60822 | F14: ='Raw Data'!J42/'Raw Data'!M42 -> 0.13762299 | G14: ='Raw Data'!I42/('Raw Data'!M42+'Raw Data'!E42) -> 0.085176052 | H14: ='Raw Data'!E42/'Raw Data'!M42 -> 1.4768489 | I14: ='Raw Data'!I42/'Raw Data'!Q42 -> -2.7176365 | J14: ='Raw Data'!I42/'Raw Data'!O42 -> 0.19495721 | K14: =IFERROR('Raw Data'!J42/'Raw Data'!O42, "") -> 0.12717838 | L14: ='Raw Data'!R42/'Raw Data'!C42 -> 0.076905689 | M14: =AVERAGE(_xlfn.RANK.EQ(C14,$C$6:$C$64,1), _xlfn.RANK.EQ(D14,$D$6:$D$64,1), _xlfn.RANK.EQ(E14,$E$6:$E$64,1) ) -> 23.666667 | N14: =AVERAGE( _xlfn.RANK.EQ(F14,$F$6:$F$64,0), _xlfn.RANK.EQ(G14,$G$6:$G$64,0), _xlfn.RANK.EQ(J14,$J$6:$J$64,0), _xlfn.RANK.EQ(K14,$K$6:$K$64,0) ) -> 25.75 | O14: =AVERAGE( _xlfn.RANK.EQ(H14,$H$6:$H$64,1), _xlfn.RANK.EQ(I14,$I$6:$I$64,0) ) -> 39 | P14: =_xlfn.RANK.EQ(L14,$L$6:$L$64,0) -> 12 | Q14: =AVERAGE(M14,N14,O14,P14) -> 25.104167 | R14: =IF(Q14<=20,"Excellent",IF(Q14<=25,"Very Good",IF(Q14<=30,"Decent",IF(Q14<=35,"Average","Weak/Avoid")))) -> Decent
A15: ='Raw Data'!B54 -> Power Grid Corporation of India Limited | B15: =COUNTIF($C$69:$L$98,A15) -> 5 | C15: =('Raw Data'!D54+'Raw Data'!E54-'Raw Data'!F54)/'Raw Data'!H54 -> 9.7057577 | D15: ='Raw Data'!C54/'Raw Data'!L54 -> 15.985706 | E15: ='Raw Data'!C54/'Raw Data'!N54 -> 2.4562542 | F15: ='Raw Data'!J54/'Raw Data'!M54 -> 0.19570228 | G15: ='Raw Data'!I54/('Raw Data'!M54+'Raw Data'!E54) -> 0.1188326 | H15: ='Raw Data'!E54/'Raw Data'!M54 -> 1.7982344 | I15: ='Raw Data'!I54/'Raw Data'!Q54 -> -3.2455377 | J15: ='Raw Data'!I54/'Raw Data'!O54 -> 0.55929563 | K15: =IFERROR('Raw Data'!J54/'Raw Data'!O54, "") -> 0.32916802 | L15: ='Raw Data'!R54/'Raw Data'!C54 -> 0.062555884 | M15: =AVERAGE(_xlfn.RANK.EQ(C15,$C$6:$C$64,1), _xlfn.RANK.EQ(D15,$D$6:$D$64,1), _xlfn.RANK.EQ(E15,$E$6:$E$64,1) ) -> 28.666667 | N15: =AVERAGE( _xlfn.RANK.EQ(F15,$F$6:$F$64,0), _xlfn.RANK.EQ(G15,$G$6:$G$64,0), _xlfn.RANK.EQ(J15,$J$6:$J$64,0), _xlfn.RANK.EQ(K15,$K$6:$K$64,0) ) -> 14.75 | O15: =AVERAGE( _xlfn.RANK.EQ(H15,$H$6:$H$64,1), _xlfn.RANK.EQ(I15,$I$6:$I$64,0) ) -> 41.5 | P15: =_xlfn.RANK.EQ(L15,$L$6:$L$64,0) -> 19 | Q15: =AVERAGE(M15,N15,O15,P15) -> 25.979167 | R15: =IF(Q15<=20,"Excellent",IF(Q15<=25,"Very Good",IF(Q15<=30,"Decent",IF(Q15<=35,"Average","Weak/Avoid")))) -> Decent
A16: ='Raw Data'!B57 -> Rudra Gas Enterprise Limited | B16: =COUNTIF($C$69:$L$98,A16) -> 5 | C16: =('Raw Data'!D57+'Raw Data'!E57-'Raw Data'!F57)/'Raw Data'!H57 -> 10.471657 | D16: ='Raw Data'!C57/'Raw Data'!L57 -> 18.287456 | E16: ='Raw Data'!C57/'Raw Data'!N57 -> 2.983093 | F16: ='Raw Data'!J57/'Raw Data'!M57 -> 0.61161086 | G16: ='Raw Data'!I57/('Raw Data'!M57+'Raw Data'!E57) -> 0.3148247 | H16: ='Raw Data'!E57/'Raw Data'!M57 -> 2.6922056 | I16: ='Raw Data'!I57/'Raw Data'!Q57 -> -2.6497038 | J16: ='Raw Data'!I57/'Raw Data'!O57 -> 0.12351956 | K16: =IFERROR('Raw Data'!J57/'Raw Data'!O57, "") -> 0.064991455 | L16: ='Raw Data'!R57/'Raw Data'!C57 -> 0.054682293 | M16: =AVERAGE(_xlfn.RANK.EQ(C16,$C$6:$C$64,1), _xlfn.RANK.EQ(D16,$D$6:$D$64,1), _xlfn.RANK.EQ(E16,$E$6:$E$64,1) ) -> 33.333333 | N16: =AVERAGE( _xlfn.RANK.EQ(F16,$F$6:$F$64,0), _xlfn.RANK.EQ(G16,$G$6:$G$64,0), _xlfn.RANK.EQ(J16,$J$6:$J$64,0), _xlfn.RANK.EQ(K16,$K$6:$K$64,0) ) -> 22 | O16: =AVERAGE( _xlfn.RANK.EQ(H16,$H$6:$H$64,1), _xlfn.RANK.EQ(I16,$I$6:$I$64,0) ) -> 42.5 | P16: =_xlfn.RANK.EQ(L16,$L$6:$L$64,0) -> 22 | Q16: =AVERAGE(M16,N16,O16,P16) -> 29.958333 | R16: =IF(Q16<=20,"Excellent",IF(Q16<=25,"Very Good",IF(Q16<=30,"Decent",IF(Q16<=35,"Average","Weak/Avoid")))) -> Decent
A17: ='Raw Data'!B45 -> Sugs Lloyd Limited | B17: =COUNTIF($C$69:$L$98,A17) -> 7 | C17: =('Raw Data'!D45+'Raw Data'!E45-'Raw Data'!F45)/'Raw Data'!H45 -> 8.5746239 | D17: ='Raw Data'!C45/'Raw Data'!L45 -> 15.441734 | E17: ='Raw Data'!C45/'Raw Data'!N45 -> 2.7615935 | F17: ='Raw Data'!J45/'Raw Data'!M45 -> 0.22074519 | G17: ='Raw Data'!I45/('Raw Data'!M45+'Raw Data'!E45) -> 0.1887728 | H17: ='Raw Data'!E45/'Raw Data'!M45 -> 0.84008365 | I17: ='Raw Data'!I45/'Raw Data'!Q45 -> -590.24996 | J17: ='Raw Data'!I45/'Raw Data'!O45 -> 0.1458978 | K17: =IFERROR('Raw Data'!J45/'Raw Data'!O45, "") -> 0.092717778 | L17: ='Raw Data'!R45/'Raw Data'!C45 -> 0.064759568 | M17: =AVERAGE(_xlfn.RANK.EQ(C17,$C$6:$C$64,1), _xlfn.RANK.EQ(D17,$D$6:$D$64,1), _xlfn.RANK.EQ(E17,$E$6:$E$64,1) ) -> 27.333333 | N17: =AVERAGE( _xlfn.RANK.EQ(F17,$F$6:$F$64,0), _xlfn.RANK.EQ(G17,$G$6:$G$64,0), _xlfn.RANK.EQ(J17,$J$6:$J$64,0), _xlfn.RANK.EQ(K17,$K$6:$K$64,0) ) -> 23.75 | O17: =AVERAGE( _xlfn.RANK.EQ(H17,$H$6:$H$64,1), _xlfn.RANK.EQ(I17,$I$6:$I$64,0) ) -> 48.5 | P17: =_xlfn.RANK.EQ(L17,$L$6:$L$64,0) -> 17 | Q17: =AVERAGE(M17,N17,O17,P17) -> 29.145833 | R17: =IF(Q17<=20,"Excellent",IF(Q17<=25,"Very Good",IF(Q17<=30,"Decent",IF(Q17<=35,"Average","Weak/Avoid")))) -> Decent
A18: ='Raw Data'!B65 -> GAIL (India) Limited | B18: =COUNTIF($C$69:$L$98,A18) -> 6 | C18: =('Raw Data'!D65+'Raw Data'!E65-'Raw Data'!F65)/'Raw Data'!H65 -> 8.5797064 | D18: ='Raw Data'!C65/'Raw Data'!L65 -> 9.1066108 | E18: ='Raw Data'!C65/'Raw Data'!N65 -> 1.2454448 | F18: ='Raw Data'!J65/'Raw Data'!M65 -> 0.17360614 | G18: ='Raw Data'!I65/('Raw Data'!M65+'Raw Data'!E65) -> 0.12040907 | H18: ='Raw Data'!E65/'Raw Data'!M65 -> 0.3221956 | I18: ='Raw Data'!I65/'Raw Data'!Q65 -> -14.054769 | J18: ='Raw Data'!I65/'Raw Data'!O65 -> 0.07489507 | K18: =IFERROR('Raw Data'!J65/'Raw Data'!O65, "") -> 0.081670157 | L18: ='Raw Data'!R65/'Raw Data'!C65 -> 0.10981034 | M18: =AVERAGE(_xlfn.RANK.EQ(C18,$C$6:$C$64,1), _xlfn.RANK.EQ(D18,$D$6:$D$64,1), _xlfn.RANK.EQ(E18,$E$6:$E$64,1) ) -> 17.333333 | N18: =AVERAGE( _xlfn.RANK.EQ(F18,$F$6:$F$64,0), _xlfn.RANK.EQ(G18,$G$6:$G$64,0), _xlfn.RANK.EQ(J18,$J$6:$J$64,0), _xlfn.RANK.EQ(K18,$K$6:$K$64,0) ) -> 31.75 | O18: =AVERAGE( _xlfn.RANK.EQ(H18,$H$6:$H$64,1), _xlfn.RANK.EQ(I18,$I$6:$I$64,0) ) -> 38.5 | P18: =_xlfn.RANK.EQ(L18,$L$6:$L$64,0) -> 7 | Q18: =AVERAGE(M18,N18,O18,P18) -> 23.645833 | R18: =IF(Q18<=20,"Excellent",IF(Q18<=25,"Very Good",IF(Q18<=30,"Decent",IF(Q18<=35,"Average","Weak/Avoid")))) -> Very Good
A19: ='Raw Data'!B28 -> Jaiprakash Power Ventures Limited | B19: =COUNTIF($C$69:$L$98,A19) -> 5 | C19: =('Raw Data'!D28+'Raw Data'!E28-'Raw Data'!F28)/'Raw Data'!H28 -> 8.7317299 | D19: ='Raw Data'!C28/'Raw Data'!L28 -> 21.056783 | E19: ='Raw Data'!C28/'Raw Data'!N28 -> 1.4103026 | F19: ='Raw Data'!J28/'Raw Data'!M28 -> -0.50892103 | G19: ='Raw Data'!I28/('Raw Data'!M28+'Raw Data'!E28) -> 0.53086176 | H19: ='Raw Data'!E28/'Raw Data'!M28 -> -2.5874409 | I19: ='Raw Data'!I28/'Raw Data'!Q28 -> -3.1933308 | J19: ='Raw Data'!I28/'Raw Data'!O28 -> 0.23258957 | K19: =IFERROR('Raw Data'!J28/'Raw Data'!O28, "") -> 0.14046289 | L19: ='Raw Data'!R28/'Raw Data'!C28 -> 0.047490635 | M19: =AVERAGE(_xlfn.RANK.EQ(C19,$C$6:$C$64,1), _xlfn.RANK.EQ(D19,$D$6:$D$64,1), _xlfn.RANK.EQ(E19,$E$6:$E$64,1) ) -> 24.333333 | N19: =AVERAGE( _xlfn.RANK.EQ(F19,$F$6:$F$64,0), _xlfn.RANK.EQ(G19,$G$6:$G$64,0), _xlfn.RANK.EQ(J19,$J$6:$J$64,0), _xlfn.RANK.EQ(K19,$K$6:$K$64,0) ) -> 23.5 | O19: =AVERAGE( _xlfn.RANK.EQ(H19,$H$6:$H$64,1), _xlfn.RANK.EQ(I19,$I$6:$I$64,0) ) -> 18 | P19: =_xlfn.RANK.EQ(L19,$L$6:$L$64,0) -> 24 | Q19: =AVERAGE(M19,N19,O19,P19) -> 22.458333 | R19: =IF(Q19<=20,"Excellent",IF(Q19<=25,"Very Good",IF(Q19<=30,"Decent",IF(Q19<=35,"Average","Weak/Avoid")))) -> Very Good
A20: ='Raw Data'!B59 -> Mahanagar Gas Limited | B20: =COUNTIF($C$69:$L$98,A20) -> 6 | C20: =('Raw Data'!D59+'Raw Data'!E59-'Raw Data'!F59)/'Raw Data'!H59 -> 7.2078981 | D20: ='Raw Data'!C59/'Raw Data'!L59 -> 11.25037 | E20: ='Raw Data'!C59/'Raw Data'!N59 -> 1.7660404 | F20: ='Raw Data'!J59/'Raw Data'!M59 -> 0.15951393 | G20: ='Raw Data'!I59/('Raw Data'!M59+'Raw Data'!E59) -> 0.18592331 | H20: ='Raw Data'!E59/'Raw Data'!M59 -> 0.036109816 | I20: ='Raw Data'!I59/'Raw Data'!Q59 -> -67.209496 | J20: ='Raw Data'!I59/'Raw Data'!O59 -> 0.14814731 | K20: =IFERROR('Raw Data'!J59/'Raw Data'!O59, "") -> 0.12267407 | L20: ='Raw Data'!R59/'Raw Data'!C59 -> 0.088885967 | M20: =AVERAGE(_xlfn.RANK.EQ(C20,$C$6:$C$64,1), _xlfn.RANK.EQ(D20,$D$6:$D$64,1), _xlfn.RANK.EQ(E20,$E$6:$E$64,1) ) -> 20.666667 | N20: =AVERAGE( _xlfn.RANK.EQ(F20,$F$6:$F$64,0), _xlfn.RANK.EQ(G20,$G$6:$G$64,0), _xlfn.RANK.EQ(J20,$J$6:$J$64,0), _xlfn.RANK.EQ(K20,$K$6:$K$64,0) ) -> 24.25 | O20: =AVERAGE( _xlfn.RANK.EQ(H20,$H$6:$H$64,1), _xlfn.RANK.EQ(I20,$I$6:$I$64,0) ) -> 36.5 | P20: =_xlfn.RANK.EQ(L20,$L$6:$L$64,0) -> 10 | Q20: =AVERAGE(M20,N20,O20,P20) -> 22.854167 | R20: =IF(Q20<=20,"Excellent",IF(Q20<=25,"Very Good",IF(Q20<=30,"Decent",IF(Q20<=35,"Average","Weak/Avoid")))) -> Very Good
A21: ='Raw Data'!B33 -> NLC India Limited | B21: =COUNTIF($C$69:$L$98,A21) -> 6 | C21: =('Raw Data'!D33+'Raw Data'!E33-'Raw Data'!F33)/'Raw Data'!H33 -> 11.608896 | D21: ='Raw Data'!C33/'Raw Data'!L33 -> 10.915305 | E21: ='Raw Data'!C33/'Raw Data'!N33 -> 1.7142982 | F21: ='Raw Data'!J33/'Raw Data'!M33 -> 0.17009693 | G21: ='Raw Data'!I33/('Raw Data'!M33+'Raw Data'!E33) -> 0.068871727 | H21: ='Raw Data'!E33/'Raw Data'!M33 -> 1.3341467 | I21: ='Raw Data'!I33/'Raw Data'!Q33 -> -2.5959215 | J21: ='Raw Data'!I33/'Raw Data'!O33 -> 0.17180173 | K21: =IFERROR('Raw Data'!J33/'Raw Data'!O33, "") -> 0.18178368 | L21: ='Raw Data'!R33/'Raw Data'!C33 -> 0.091614479 | M21: =AVERAGE(_xlfn.RANK.EQ(C21,$C$6:$C$64,1), _xlfn.RANK.EQ(D21,$D$6:$D$64,1), _xlfn.RANK.EQ(E21,$E$6:$E$64,1) ) -> 24.666667 | N21: =AVERAGE( _xlfn.RANK.EQ(F21,$F$6:$F$64,0), _xlfn.RANK.EQ(G21,$G$6:$G$64,0), _xlfn.RANK.EQ(J21,$J$6:$J$64,0), _xlfn.RANK.EQ(K21,$K$6:$K$64,0) ) -> 25.25 | O21: =AVERAGE( _xlfn.RANK.EQ(H21,$H$6:$H$64,1), _xlfn.RANK.EQ(I21,$I$6:$I$64,0) ) -> 36 | P21: =_xlfn.RANK.EQ(L21,$L$6:$L$64,0) -> 9 | Q21: =AVERAGE(M21,N21,O21,P21) -> 23.729167 | R21: =IF(Q21<=20,"Excellent",IF(Q21<=25,"Very Good",IF(Q21<=30,"Decent",IF(Q21<=35,"Average","Weak/Avoid")))) -> Very Good
A22: ='Raw Data'!B24 -> Pace Digitek Limited | B22: =COUNTIF($C$69:$L$98,A22) -> 7 | C22: =('Raw Data'!D24+'Raw Data'!E24-'Raw Data'!F24)/'Raw Data'!H24 -> 11.405448 | D22: ='Raw Data'!C24/'Raw Data'!L24 -> 14.341665 | E22: ='Raw Data'!C24/'Raw Data'!N24 -> 2.7339329 | F22: ='Raw Data'!J24/'Raw Data'!M24 -> 0.30279491 | G22: ='Raw Data'!I24/('Raw Data'!M24+'Raw Data'!E24) -> 0.38550875 | H22: ='Raw Data'!E24/'Raw Data'!M24 -> 0.18594467 | I22: ='Raw Data'!I24/'Raw Data'!Q24 -> -11.412597 | J22: ='Raw Data'!I24/'Raw Data'!O24 -> 0.17243435 | K22: =IFERROR('Raw Data'!J24/'Raw Data'!O24, "") -> 0.11420199 | L22: ='Raw Data'!R24/'Raw Data'!C24 -> 0.069726913 | M22: =AVERAGE(_xlfn.RANK.EQ(C22,$C$6:$C$64,1), _xlfn.RANK.EQ(D22,$D$6:$D$64,1), _xlfn.RANK.EQ(E22,$E$6:$E$64,1) ) -> 29.333333 | N22: =AVERAGE( _xlfn.RANK.EQ(F22,$F$6:$F$64,0), _xlfn.RANK.EQ(G22,$G$6:$G$64,0), _xlfn.RANK.EQ(J22,$J$6:$J$64,0), _xlfn.RANK.EQ(K22,$K$6:$K$64,0) ) -> 19 | O22: =AVERAGE( _xlfn.RANK.EQ(H22,$H$6:$H$64,1), _xlfn.RANK.EQ(I22,$I$6:$I$64,0) ) -> 35.5 | P22: =_xlfn.RANK.EQ(L22,$L$6:$L$64,0) -> 13 | Q22: =AVERAGE(M22,N22,O22,P22) -> 24.208333 | R22: =IF(Q22<=20,"Excellent",IF(Q22<=25,"Very Good",IF(Q22<=30,"Decent",IF(Q22<=35,"Average","Weak/Avoid")))) -> Very Good
